Workbook

Sheet summary
B2: listening | C2: 正解率 | D2: 問題数 | E2: 正解率
B3: 1 | C3: =SUM(listening!C3:C12) -> 8 | D3: 10 | E3: =C3/D3 -> 0.8
B4: 2 | C4: =SUM(listening!C13:C42) -> 24 | D4: 30 | E4: =C4/D4 -> 0.8
B5: 3 | C5: =SUM(listening!C43:C72) -> 17 | D5: 30 | E5: =C5/D5 -> 0.56666667
B6: 4 | C6: =SUM(listening!C73:C102) -> 22 | D6: 30 | E6: =C6/D6 -> 0.73333333
B8: reading | C8: 正解率 | D8: 問題数 | E8: 正解率
B9: 5 | C9: =SUM(reading!C3:C42) -> 22 | D9: 40 | E9: =C9/D9 -> 0.55
B10: 6 | C10: =SUM(reading!C43:C54) -> 10 | D10: 12 | E10: =C10/D10 -> 0.83333333
B11: 7 | C11: =SUM(reading!C55:C102) -> 22 | D11: 48 | E11: =C11/D11 -> 0.45833333

Sheet listening
C1: =SUM(C3:C102) -> 71
A2: 問題番号 | B2: 解答 | C2: 正誤
A3: 1 | B3: D | C3: 1
A4: 2 | B4: B | C4: 0
A5: =A4+1 -> 3 | B5: C | C5: 1
A6: =A5+1 -> 4 | B6: B | C6: 1
A7: =A6+1 -> 5 | B7: A | C7: 1
A8: =A7+1 -> 6 | B8: B | C8: 1
A9: =A8+1 -> 7 | B9: D | C9: 1
A10: =A9+1 -> 8 | B10: D | C10: 1
A11: =A10+1 -> 9 | B11: C | C11: 1
A12: =A11+1 -> 10 | B12: C | C12: 0
A13: =A12+1 -> 11 | B13: A | C13: 1
A14: =A13+1 -> 12 | B14: C | C14: 1
A15: =A14+1 -> 13 | B15: B | C15: 1
A16: =A15+1 -> 14 | B16: C | C16: 1
... A60: =A59+1 -> 58 | B60: B | C60: 1
A61: =A60+1 -> 59
A62: =A61+1 -> 60
A63: =A62+1 -> 61
A64: =A63+1 -> 62
A65: =A64+1 -> 63
A66: =A65+1 -> 64
A67: =A66+1 -> 65
A68: =A67+1 -> 66
A69: =A68+1 -> 67
A70: =A69+1 -> 68
A71: =A70+1 -> 69
A72: =A71+1 -> 70
A73: =A72+1 -> 71 | B73: C | C73: 0
A74: =A73+1 -> 72 | B74: A | C74: 1
A75: =A74+1 -> 73 | B75: B | C75: 1
A76: =A75+1 -> 74 | B76: C | C76: 1
A77: =A76+1 -> 75 | B77: C | C77: 0
A78: =A77+1 -> 76 | B78: B | C78: 0
A79: =A78+1 -> 77 | B79: D | C79: 1
A80: =A79+1 -> 78 | B80: B | C80: 1
A81: =A80+1 -> 79 | B81: A | C81: 1
A82: =A81+1 -> 80 | B82: B | C82: 1
A83: =A82+1 -> 81 | B83: D | C83: 1
...

Sheet reading
C1: =SUM(C3:C102) -> 54
A2: 問題番号 | B2: 解答 | C2: 正誤
A3: 101 | B3: C | C3: 0
A4: =A3+1 -> 102 | B4: C | C4: 1
A5: =A4+1 -> 103 | B5: D | C5: 1
A6: =A5+1 -> 104 | B6: B | C6: 1
A7: =A6+1 -> 105 | B7: C | C7: 1
A8: =A7+1 -> 106 | B8: D | C8: 1
A9: =A8+1 -> 107 | B9: C | C9: 1
A10: =A9+1 -> 108 | B10: B | C10: 0
A11: =A10+1 -> 109 | B11: A | C11: 1
A12: =A11+1 -> 110 | B12: A | C12: 1
A13: =A12+1 -> 111 | B13: B | C13: 0
A14: =A13+1 -> 112 | B14: C | C14: 1
A15: =A14+1 -> 113 | B15: B | C15: 1
... A32: =A31+1 -> 130 | B32: A | C32: 0
A33: =A32+1 -> 131
A34: =A33+1 -> 132
A35: =A34+1 -> 133
A36: =A35+1 -> 134
A37: =A36+1 -> 135
A38: =A37+1 -> 136
A39: =A38+1 -> 137
A40: =A39+1 -> 138
A41: =A40+1 -> 139
A42: =A41+1 -> 140
A43: =A42+1 -> 141 | B43: B | C43: 1
A44: =A43+1 -> 142 | B44: D | C44: 1
A45: =A44+1 -> 143 | B45: A | C45: 1
A46: =A45+1 -> 144 | B46: A | C46: 1
A47: =A46+1 -> 145 | B47: D | C47: 1
A48: =A47+1 -> 146 | B48: C | C48: 1
A49: =A48+1 -> 147 | B49: A | C49: 1
A50: =A49+1 -> 148 | B50: D | C50: 1
A51: =A50+1 -> 149 | B51: C | C51: 1
A52: =A51+1 -> 150 | B52: A | C52: 0
A53: =A52+1 -> 151 | B53: B | C53: 0
A54: =A53+1 -> 152 | B54: D | C54: 1
... A82: =A81+1 -> 180 | B82: B | C82: 1
A83: =A82+1 -> 181
...
