Workbook

Sheet summary
B2: listening | C2: 正解率 | D2: 問題数 | E2: 正解率
B3: 1 | C3: =SUM(listening!C3:C12) -> 0 | D3: 10 | E3: =C3/D3 -> 0
B4: 2 | C4: =SUM(listening!C13:C42) -> 0 | D4: 30 | E4: =C4/D4 -> 0
B5: 3 | C5: =SUM(listening!C43:C72) -> 0 | D5: 30 | E5: =C5/D5 -> 0
B6: 4 | C6: =SUM(listening!C73:C102) -> 0 | D6: 30 | E6: =C6/D6 -> 0
B8: reading | C8: 正解率 | D8: 問題数 | E8: 正解率
B9: 5 | C9: =SUM(reading!C3:C42) -> 36 | D9: 40 | E9: =C9/D9 -> 0.9
B10: 6 | C10: =SUM(reading!C43:C54) -> 9 | D10: 12 | E10: =C10/D10 -> 0.75
B11: 7 | C11: =SUM(reading!C55:C102) -> 18 | D11: 48 | E11: =C11/D11 -> 0.375

Sheet listening
C1: =SUM(C3:C102) -> 0
A2: 問題番号 | B2: 解答 | C2: 正誤
A3: 1
A4: 2
A5: =A4+1 -> 3
A6: =A5+1 -> 4
A7: =A6+1 -> 5
A8: =A7+1 -> 6
A9: =A8+1 -> 7
A10: =A9+1 -> 8
A11: =A10+1 -> 9
A12: =A11+1 -> 10
A13: =A12+1 -> 11
A14: =A13+1 -> 12
A15: =A14+1 -> 13
A16: =A15+1 -> 14
... A102: =A101+1 -> 100

Sheet reading
C1: =SUM(C3:C102) -> 63
A2: 問題番号 | B2: 解答 | C2: 正誤
A3: 101 | B3: A | C3: 1
A4: =A3+1 -> 102 | B4: D | C4: 1
A5: =A4+1 -> 103 | B5: D | C5: 1
A6: =A5+1 -> 104 | B6: D | C6: 1
A7: =A6+1 -> 105 | B7: C | C7: 1
A8: =A7+1 -> 106 | B8: A | C8: 1
A9: =A8+1 -> 107 | B9: C | C9: 0
A10: =A9+1 -> 108 | B10: A | C10: 1
A11: =A10+1 -> 109 | B11: B | C11: 0
A12: =A11+1 -> 110 | B12: B | C12: 1
A13: =A12+1 -> 111 | B13: B | C13: 1
A14: =A13+1 -> 112 | B14: A | C14: 1
A15: =A14+1 -> 113 | B15: A | C15: 1
A16: =A15+1 -> 114 | B16: D | C16: 1
A17: =A16+1 -> 115 | B17: C | C17: 1 | F17: pay for
A18: =A17+1 -> 116 | B18: C | C18: 1 | F18: except for
A19: =A18+1 -> 117 | B19: B | C19: 1
A20: =A19+1 -> 118 | B20: C | C20: 1
A21: =A20+1 -> 119 | B21: B | C21: 1
A22: =A21+1 -> 120 | B22: C | C22: 1
A23: =A22+1 -> 121 | B23: A | C23: 1
A24: =A23+1 -> 122 | B24: C | C24: 0
A25: =A24+1 -> 123 | B25: B | C25: 1
A26: =A25+1 -> 124 | B26: A | C26: 1 | F26: lucrative
A27: =A26+1 -> 125 | B27: D | C27: 1 | F27: lucrative
A28: =A27+1 -> 126 | B28: B | C28: 1 | F28: lucrative
A29: =A28+1 -> 127 | B29: C | C29: 1
A30: =A29+1 -> 128 | B30: D | C30: 1
A31: =A30+1 -> 129 | B31: B | C31: 1
A32: =A31+1 -> 130 | B32: B | C32: 1
A33: =A32+1 -> 131 | B33: D | C33: 1
A34: =A33+1 -> 132 | B34: A | C34: 1
A35: =A34+1 -> 133 | B35: C | C35: 1 | F35: note | G35: 留意する
A36: =A35+1 -> 134 | B36: B | C36: 1
A37: =A36+1 -> 135 | B37: B | C37: 1
A38: =A37+1 -> 136 | B38: A | C38: 1
A39: =A38+1 -> 137 | B39: C | C39: 1
A40: =A39+1 -> 138 | B40: D | C40: 1
...

Sheet review
A2: 問題番号 | B2: 解答 | C2: 正誤
A3: 101 | B3: A | C3: 1 | D3: 1
A4: =A3+1 -> 102 | B4: A | C4: 1 | D4: 0
A5: =A4+1 -> 103 | B5: B | C5: 0 | D5: 0
A6: =A5+1 -> 104 | B6: B | C6: 1 | D6: 1
A7: =A6+1 -> 105 | B7: C | C7: 1 | D7: 1
A8: =A7+1 -> 106 | B8: C | C8: 1 | D8: 0
A9: =A8+1 -> 107 | B9: B | C9: 0 | D9: 1
A10: =A9+1 -> 108 | B10: A | C10: 1 | D10: 1
A11: =A10+1 -> 109 | B11: A | C11: 0 | D11: 1
A12: =A11+1 -> 110 | B12: D | C12: 1 | D12: 1
A13: 111 | B13: A | C13: 1
A14: 112 | B14: C | C14: 1
A15: 113 | B15: B | C15: 1
A16: 114 | B16: A | C16: 1
A17: 115 | B17: A | C17: 0
A18: 116 | B18: C | C18: 1
A19: 117 | B19: D | C19: 1
A20: 118 | B20: C | C20: 0
A21: 119 | B21: B | C21: 0
A22: 120 | B22: A | C22: 0
A23: 111 | B23: A | C23: 1
A24: 112 | B24: C | C24: 1
... A33: 131 | B33: B | C33: 1
A34: =A33+1 -> 132 | B34: A | C34: 1
A35: =A34+1 -> 133 | B35: A | C35: 1
A36: =A35+1 -> 134 | B36: C | C36: 1
A37: =A36+1 -> 135 | B37: B | C37: 1
A38: =A37+1 -> 136 | B38: C | C38: 1
A39: =A38+1 -> 137 | B39: D | C39: 1
A40: =A39+1 -> 138 | B40: D | C40: 1
A41: =A40+1 -> 139 | B41: C | C41: 0
A42: =A41+1 -> 140 | B42: D | C42: 1
A43: =A42+1 -> 141 | B43: B | C43: 1
A44: =A43+1 -> 142 | B44: A | C44: 1
A45: =A44+1 -> 143 | B45: C | C45: 1
... A48: =A47+1 -> 146 | B48: D | C48: 1
A49: 155 | B49: B | C49: 1
A50: 156 | B50: A | C50: 1
A51: 157 | B51: C | C51: 1
...

Sheet Sheet1
B3: x
B4: 0 | C4: =2*PI()*B4^2+10000/B4 -> #DIV/0!
B5: =B4+0.1 -> 0.1 | C5: =2*PI()*B5^2+100000/B5 -> 1000000.1
B6: =B5+0.1 -> 0.2 | C6: =2*PI()*B6^2+100000/B6 -> 500000.25
B7: =B6+0.1 -> 0.3 | C7: =2*PI()*B7^2+100000/B7 -> 333333.9
B8: =B7+0.1 -> 0.4 | C8: =2*PI()*B8^2+100000/B8 -> 250001.01
B9: =B8+0.1 -> 0.5 | C9: =2*PI()*B9^2+100000/B9 -> 200001.57
B10: =B9+0.1 -> 0.6 | C10: =2*PI()*B10^2+100000/B10 -> 166668.93
B11: =B10+0.1 -> 0.7 | C11: =2*PI()*B11^2+100000/B11 -> 142860.22
B12: =B11+0.1 -> 0.8 | C12: =2*PI()*B12^2+100000/B12 -> 125004.02
B13: =B12+0.1 -> 0.9 | C13: =2*PI()*B13^2+100000/B13 -> 111116.2
B14: =B13+0.1 -> 1 | C14: =2*PI()*B14^2+100000/B14 -> 100006.28
B15: =B14+0.1 -> 1.1 | C15: =2*PI()*B15^2+100000/B15 -> 90916.694
B16: =B15+0.1 -> 1.2 | C16: =2*PI()*B16^2+100000/B16 -> 83342.381
... B309: =B308+0.1 -> 30.5 | C309: =2*PI()*B309^2+100000/B309 -> 9123.6217
